Workbook

Sheet Guide
A1: Time Value of Money — financial models built from the lecture slides
A2: Source: Foundations of Finance, 'compound_interest_formulas.pdf' (35 slides). Every model sheet lets you solve the slide's equation for any variable.
A4: HOW TO READ THE SHEETS
A5: Input (edit me) | B5: Blue text on yellow = a number you can change. Rates go in as percentages (8% or 0.08 — never 8).
A6: Formula | B6: Black = calculated. Don't type over these; change the yellow inputs instead.
A7: Solved variable | B7: Green = the variable the 'Solve for' dropdown is currently solving. Its yellow input is ignored.
A8: Link to another sheet | B8: Green text = pulled from another sheet (the credit-card schedule reads the annuity solver).
A9: Slide answer | B9: Blue = the number printed on the slide, typed in as a check. 'Match?' compares the model to it.
A11: SHEET MAP
A12: Sheet | B12: What it models | C12: Slides
A13: 1 Single Cash Flow | B13: FV = PV(1+R)^T solved for FV, PV, R or T; interest decomposition; every slide example; FV/PV tables and charts | C13: 4–16
A14: 2 Multiple Cash Flows | B14: PV and FV of any stream of cash flows, period by period; NPV cross-check; office-building example | C14: 17–21
A15: 3 Perpetuities | B15: PV = CF/R and PV = CF/(R−g) solved for any variable; 100-period convergence table and chart | C15: 22–25
A16: 4 Annuities | B16: Level and growing annuity solved for PV, CF, T (and R); derivation as perpetuity minus perpetuity; FV of an annuity; credit-card questions | C16: 26–28
A17: 5 Credit Card Schedule | B17: Month-by-month balance for the level and growing payment plans, plus the savings comparison | C17: 27–28
A18: 6 Compounding & EAR | B18: APR ↔ EAR for any m, continuous compounding, FV under different frequencies, payday-loan example | C18: 29–34
A20: FORMULA CHEAT SHEET — one equation per topic, and the same equation rearranged
A21: Topic | B21: Slide formula | C21: Rearranged for the other variables
A22: Future value (slide 5) | B22: FV = PV × (1 + R)^T | C22: PV = FV / (1+R)^T · R = (FV/PV)^(1/T) − 1 · T = ln(FV/PV) / ln(1+R)
A23: Present value (slide 9) | B23: PV = FV / (1 + R)^T | C23: Same equation as above, read the other way: discounting is compounding in reverse
A24: Yield R (slide 12) | B24: R = (FV / PV)^(1/T) − 1 | C24: Take the T-th root of the total growth factor FV/PV
A25: Time T (slide 12) | B25: T = ln(FV / PV) / ln(1 + R) | C25: Logs turn the exponent into a multiplier; any log base works
A26: Multiple cash flows (slide 17) | B26: PV = Σ CFₜ/(1+R)^t FV = Σ CFₜ(1+R)^(T−t) | C26: FV = PV × (1+R)^T still holds for the whole stream
A27: Perpetuity (slide 22) | B27: PV = CF / R | C27: CF = PV × R · R = CF / PV
A28: Growing perpetuity (slide 24) | B28: PV = CF / (R − g) (g < R) | C28: CF = PV(R−g) · R = CF/PV + g · g = R − CF/PV
A29: Annuity (slide 26) | B29: PV = CF/R × [1 − 1/(1+R)^T] | C29: CF = PV·R / [1 − 1/(1+R)^T] · T = −ln(1 − PV·R/CF) / ln(1+R) · R: no closed form → RATE()
A30: Growing annuity (slide 26) | B30: PV = CF/(R−g) × [1 − (1+g)^T/(1+R)^T] | C30: CF = PV(R−g) / [1 − ((1+g)/(1+R))^T] · T = ln(1 − PV(R−g)/CF) / ln((1+g)/(1+R))
A31: FV of an annuity (slide 28) | B31: FV = CF × [(1+R)^T − 1] / R | C31: = PV of the annuity × (1+R)^T
A32: Effective annual rate (slide 29) | B32: EAR = (1 + APR/m)^m − 1 | C32: APR = m × [(1+EAR)^(1/m) − 1] · rate per period = APR/m
... A34: FV with compounding m times a year (slide 32) | B34: FV = PV(1 + APR/m)^(T·m) = PV(1+EAR)^T | C34: Continuous: FV = PV × e^(R·T)
A37: COMMON MISTAKES (including the ones in the sheet you started)
A38: Rate typed as 6 instead of 6% | B38: Excel reads 6 as 600%. Your T came out as −3.66 because ln(FV/PV)/ln(1+6) was evaluated with a 600% rate. Type 6% or 0.06.
A39: FV smaller than PV when solving for T | B39: ln(FV/PV) is negative when FV < PV, so T is negative. Your inputs were FV = 400 and PV = 500,000 (the slide uses 500 thousand → 4,000 thousand, same units).
A40: DIV/0 errors in the annuity block | B40: The rate and time cells were empty, so the formula divided by zero. Every solver here ships with the slide's numbers already filled in.
A41: Mixing periods | B41: A monthly rate needs T in months (1.5% and 48), an annual rate needs T in years. Never 1.5% with T = 4.
A42: Timing of the first cash flow | B42: Perpetuity and annuity formulas assume the first CF arrives one period from now (t = 1), not today.
A43: g ≥ R in a growing perpetuity | B43: The formula only works when g < R; otherwise the cash flows outgrow the discounting and PV is infinite.
A44: Excel's sign convention | B44: PV(), FV(), PMT(), RATE(), NPER() treat money paid out as negative — hence the minus signs in the cross-check cells.

Sheet 1 Single Cash Flow
A1: Single cash flow: FV = PV × (1 + R)^T (slides 4–16)
A2: One equation, four unknowns. Enter the three you know, pick the fourth in 'Solve for'. Yellow = your inputs, black = formulas, green = the solved variable.
A4: A. SOLVER — the same equation rearranged for each variable
A5: Variable | B5: Your input | C5: Value used / solved | D5: Formula (algebra)
A6: Solve for | B6: T | D6: Choose FV, PV, R or T. The input in that row is ignored and replaced by the solved value.
A7: Present value PV (money today; here $ thousand) | B7: 500 | C7: =IF($B$6="PV",B8/(1+B9)^B10,B7) -> 500 | D7: PV = FV / (1 + R)^T (discount FV back T periods)
A8: Future value FV (money at time T) | B8: 4000 | C8: =IF($B$6="FV",B7*(1+B9)^B10,B8) -> 4000 | D8: FV = PV × (1 + R)^T (compound PV forward T periods)
A9: Rate per period R (enter 8% or 0.08, never 8) | B9: 0.08 | C9: =IF($B$6="R",(B8/B7)^(1/B10)-1,B9) -> 0.08 | D9: R = (FV / PV)^(1/T) − 1 (the yield: T-th root of the growth factor)
A10: Number of periods T (same unit as R: years with an annual R) | C10: =IF($B$6="T",LN(B8/B7)/LN(1+B9),B10) -> 27.019405 | D10: T = ln(FV / PV) / ln(1 + R) (take logs of both sides of FV = PV(1+R)^T)
A11: Answer | B11: =IF($B$6="R",TEXT(C9,"0.00%"),IF($B$6="T",TEXT(C10,"0.00")&" periods",IF($B$6="PV",TEXT(C7,"#,##0.00"),TEXT(C8,"#,##0.00")))) -> 27.02 periods | D11: ="Solved for "&$B$6&" from the other three inputs" -> Solved for T from the other three inputs
A12: Excel built-in function (cross-check) | B12: =IF($B$6="PV",PV(B9,B10,0,-B8),IF($B$6="FV",FV(B9,B10,0,-B7),IF($B$6="R",RATE(B10,0,-B7,B8),NPER(B9,0,-B7,B8)))) -> 27.019405 | D12: =PV(R,T,0,−FV) · =FV(R,T,0,−PV) · =RATE(T,0,−PV,FV) · =NPER(R,0,−PV,FV). Excel's sign rule: money you pay out is negative.
A13: Consistency check: FV = PV × (1 + R)^T ? | B13: =IF(ABS(C8-C7*(1+C9)^C10)<0.000001*MAX(1,ABS(C8)),"OK ✓","mismatch ✗") -> OK ✓ | D13: Uses the 'Value used' column, so it always holds once one variable is solved.
A15: Interest decomposition (slide 4): FV = PV + simple interest + interest on interest
A16: Simple interest = PV × R × T | B16: =C7*C9*C10 -> 1080.7762 | D16: What you would earn if interest were paid only on the original PV
A17: Interest on interest = FV − PV − simple interest | B17: =C8-C7-B16 -> 2419.2238 | D17: The compounding effect — it grows faster than linearly with T (see chart below)
A18: Total growth = FV − PV | B18: =C8-C7 -> 3500
A20: B. WORKED EXAMPLES FROM THE SLIDES — each row applies the rearranged formula directly
A21: Example | B21: Solve for | C21: Slide | D21: Formula used | E21: PV | F21: FV | G21: R | H21: T | I21: Model result | J21: Slide answer | K21: Match?
A22: Manhattan: $24 in 1626, 399 years at 5% (what is it worth?) | B22: FV | C22: 6–7 | D22: FV = PV × (1+R)^T | E22: 24 | F22: — | G22: 0.05 | H22: 399 | I22: =E22*(1+G22)^H22 -> 6.835048e+09 | J22: 6840000000 | K22: =IF(ABS(I22-J22)/ABS(J22)<0.005,"✓","✗") -> ✓
A23: Manhattan: same $24 at 6% — one point of rate, 44× the answer | B23: FV | C23: 6–7 | D23: FV = PV × (1+R)^T | E23: 24 | F23: — | G23: 0.06 | H23: 399 | I23: =E23*(1+G23)^H23 -> 3.0008997e+11 | J23: 300000000000 | K23: =IF(ABS(I23-J23)/ABS(J23)<0.005,"✓","✗") -> ✓
A24: GM pension: $45 billion due in 15 years, discount rate 6% ($ bn) | B24: PV | C24: 10–11 | D24: PV = FV / (1+R)^T | E24: — | F24: 45 | G24: 0.06 | H24: 15 | I24: =F24/(1+G24)^H24 -> 18.776928 | J24: 18.78 | K24: =IF(ABS(I24-J24)/ABS(J24)<0.005,"✓","✗") -> ✓
A25: GM pension: same liability at 4% — lower rate, bigger PV ($ bn) | B25: PV | C25: 10–11 | D25: PV = FV / (1+R)^T | E25: — | F25: 45 | G25: 0.04 | H25: 15 | I25: =F25/(1+G25)^H25 -> 24.986903 | J25: 24.99 | K25: =IF(ABS(I25-J25)/ABS(J25)<0.005,"✓","✗") -> ✓
A26: Microsoft: raise $1.3 bn now, repay $2.5 bn in 25 years — yield? | B26: R | C26: 13–14 | D26: R = (FV/PV)^(1/T) − 1 | E26: 1.3 | F26: 2.5 | G26: — | H26: 25 | I26: =(F26/E26)^(1/H26)-1 -> 0.026502157 | J26: 0.0265 | K26: =IF(ABS(I26-J26)/ABS(J26)<0.005,"✓","✗") -> ✓
A27: Aunt: $500k → $4m at 8% — years until she can retire | B27: T | C27: 15–16 | D27: T = ln(FV/PV) / ln(1+R) | E27: 500 | F27: 4000 | G27: 0.08 | H27: — | I27: =LN(F27/E27)/LN(1+G27) -> 27.019405 | J27: 27 | K27: =IF(ABS(I27-J27)/ABS(J27)<0.005,"✓","✗") -> ✓
A28: Aunt: same goal at 4% — works until 93 | B28: T | C28: 15–16 | D28: T = ln(FV/PV) / ln(1+R) | E28: 500 | F28: 4000 | G28: 0.04 | H28: — | I28: =LN(F28/E28)/LN(1+G28) -> 53.018963 | J28: 53 | K28: =IF(ABS(I28-J28)/ABS(J28)<0.005,"✓","✗") -> ✓
A29: $100 invested 2 years at 5% (slide 4) | B29: FV | C29: 4 | D29: FV = PV × (1+R)^T | E29: 100 | F29: — | G29: 0.05 | H29: 2 | I29: =E29*(1+G29)^H29 -> 110.25 | J29: 110.25 | K29: =IF(ABS(I29-J29)/ABS(J29)<0.005,"✓","✗") -> ✓
A30: $100 received in 2 years, discounted at 5% (slide 8) | B30: PV | C30: 8 | D30: PV = FV / (1+R)^T | E30: — | F30: 100 | G30: 0.05 | H30: 2 | I30: =F30/(1+G30)^H30 -> 90.702948 | J30: 90.7 | K30: =IF(ABS(I30-J30)/ABS(J30)<0.005,"✓","✗") -> ✓
A31: Slide answers are rounded (e.g. 27 years is really 27.0; 2.65% is 2.6499%). 'Match?' allows 0.5% rounding difference.
A33: C. FV AND PV OF $100 ACROSS RATES AND YEARS (slides 5 and 9) — edit the amount or the rates
A34: Amount (invested today for FV; received in year T for PV) | B34: 100
A35: Rates (edit the yellow cells) → | B35: 0 | C35: 0.05 | D35: 0.1 | E35: 0.15 | G35: PV table uses the same rates → | H35: =B35 -> 0 | I35: =C35 -> 0.05 | J35: =D35 -> 0.1 | K35: =E35 -> 0.15
A36: Year | B36: ="FV at R = "&TEXT(B35,"0%") -> FV at R = 0% | C36: ="FV at R = "&TEXT(C35,"0%") -> FV at R = 5% | D36: ="FV at R = "&TEXT(D35,"0%") -> FV at R = 10% | E36: ="FV at R = "&TEXT(E35,"0%") -> FV at R = 15% | G36: Year | H36: ="PV at R = "&TEXT(H35,"0%") -> PV at R = 0% | I36: ="PV at R = "&TEXT(I35,"0%") -> PV at R = 5% | J36: ="PV at R = "&TEXT(J35,"0%") -> PV at R = 10% | K36: ="PV at R = "&TEXT(K35,"0%") -> PV at R = 15%
A37: 0 | B37: =$B$34*(1+B$35)^$A37 -> 100 | C37: =$B$34*(1+C$35)^$A37 -> 100 | D37: =$B$34*(1+D$35)^$A37 -> 100 | E37: =$B$34*(1+E$35)^$A37 -> 100 | G37: 0 | H37: =$B$34/(1+H$35)^$G37 -> 100 | I37: =$B$34/(1+I$35)^$G37 -> 100 | J37: =$B$34/(1+J$35)^$G37 -> 100 | K37: =$B$34/(1+K$35)^$G37 -> 100
A38: 1 | B38: =$B$34*(1+B$35)^$A38 -> 100 | C38: =$B$34*(1+C$35)^$A38 -> 105 | D38: =$B$34*(1+D$35)^$A38 -> 110 | E38: =$B$34*(1+E$35)^$A38 -> 115 | G38: 1 | H38: =$B$34/(1+H$35)^$G38 -> 100 | I38: =$B$34/(1+I$35)^$G38 -> 95.238095 | J38: =$B$34/(1+J$35)^$G38 -> 90.909091 | K38: =$B$34/(1+K$35)^$G38 -> 86.956522
A39: 2 | B39: =$B$34*(1+B$35)^$A39 -> 100 | C39: =$B$34*(1+C$35)^$A39 -> 110.25 | D39: =$B$34*(1+D$35)^$A39 -> 121 | E39: =$B$34*(1+E$35)^$A39 -> 132.25 | G39: 2 | H39: =$B$34/(1+H$35)^$G39 -> 100 | I39: =$B$34/(1+I$35)^$G39 -> 90.702948 | J39: =$B$34/(1+J$35)^$G39 -> 82.644628 | K39: =$B$34/(1+K$35)^$G39 -> 75.614367
A40: 3 | B40: =$B$34*(1+B$35)^$A40 -> 100 | C40: =$B$34*(1+C$35)^$A40 -> 115.7625 | D40: =$B$34*(1+D$35)^$A40 -> 133.1 | E40: =$B$34*(1+E$35)^$A40 -> 152.0875 | G40: 3 | H40: =$B$34/(1+H$35)^$G40 -> 100 | I40: =$B$34/(1+I$35)^$G40 -> 86.38376 | J40: =$B$34/(1+J$35)^$G40 -> 75.13148 | K40: =$B$34/(1+K$35)^$G40 -> 65.751623
A41: 4 | B41: =$B$34*(1+B$35)^$A41 -> 100 | C41: =$B$34*(1+C$35)^$A41 -> 121.55062 | D41: =$B$34*(1+D$35)^$A41 -> 146.41 | E41: =$B$34*(1+E$35)^$A41 -> 174.90062 | G41: 4 | H41: =$B$34/(1+H$35)^$G41 -> 100 | I41: =$B$34/(1+I$35)^$G41 -> 82.270247 | J41: =$B$34/(1+J$35)^$G41 -> 68.301346 | K41: =$B$34/(1+K$35)^$G41 -> 57.175325
A42: 5 | B42: =$B$34*(1+B$35)^$A42 -> 100 | C42: =$B$34*(1+C$35)^$A42 -> 127.62816 | D42: =$B$34*(1+D$35)^$A42 -> 161.051 | E42: =$B$34*(1+E$35)^$A42 -> 201.13572 | G42: 5 | H42: =$B$34/(1+H$35)^$G42 -> 100 | I42: =$B$34/(1+I$35)^$G42 -> 78.352617 | J42: =$B$34/(1+J$35)^$G42 -> 62.092132 | K42: =$B$34/(1+K$35)^$G42 -> 49.717674
A43: 6 | B43: =$B$34*(1+B$35)^$A43 -> 100 | C43: =$B$34*(1+C$35)^$A43 -> 134.00956 | D43: =$B$34*(1+D$35)^$A43 -> 177.1561 | E43: =$B$34*(1+E$35)^$A43 -> 231.30608 | G43: 6 | H43: =$B$34/(1+H$35)^$G43 -> 100 | I43: =$B$34/(1+I$35)^$G43 -> 74.62154 | J43: =$B$34/(1+J$35)^$G43 -> 56.447393 | K43: =$B$34/(1+K$35)^$G43 -> 43.23276
A44: 7 | B44: =$B$34*(1+B$35)^$A44 -> 100 | C44: =$B$34*(1+C$35)^$A44 -> 140.71004 | D44: =$B$34*(1+D$35)^$A44 -> 194.87171 | E44: =$B$34*(1+E$35)^$A44 -> 266.00199 | G44: 7 | H44: =$B$34/(1+H$35)^$G44 -> 100 | I44: =$B$34/(1+I$35)^$G44 -> 71.068133 | J44: =$B$34/(1+J$35)^$G44 -> 51.315812 | K44: =$B$34/(1+K$35)^$G44 -> 37.593704
...

Sheet 2 Multiple Cash Flows
A1: Multiple cash flows: PV = Σ CFₜ / (1+R)^t FV = Σ CFₜ × (1+R)^(T−t) (slides 17–21)
A2: Value each cash flow separately at the same date, then add. Default = office building: rent $40k for 5 years, then sell for $500k (slide 20).
A4: INPUTS
A5: Discount rate per period R | B5: 0.06
A6: Horizon T (the date at which FV is measured) | B6: 5
A7: Units | B7: $ thousand
A8: Type cash flows in the yellow column below (t = 1 is one period from today). Leave unused periods blank. Year 5 = 40 rent + 500 sale = 540.
A10: RESULTS
A11: Metric | B11: Model | C11: Slide answer | D11: Match?
A12: PV of all cash flows = Σ CFₜ / (1+R)^t (price to pay today) | B12: =SUM(D20:D49) -> 542.12364 | C12: 542.12 | D12: =IF(ABS(B12-C12)<0.01,"✓","✗") -> ✓
A13: FV at T of all cash flows = Σ CFₜ × (1+R)^(T−t) (cash at T if each flow is reinvested) | B13: =SUM(F20:F49) -> 725.48372 | C13: 725.48 | D13: =IF(ABS(B13-C13)<0.01,"✓","✗") -> ✓
A14: Check: FV = PV × (1+R)^T (slide 17: 'as before') | B14: =B12*(1+B5)^B6 -> 725.48372 | D14: =IF(ABS(B14-B13)<0.000001*MAX(1,ABS(B13)),"✓ same","✗") -> ✓ same
A15: Check with Excel's =NPV(R, cash-flow range) (assumes first flow at t = 1) | B15: =NPV(B5,B20:B49) -> 542.12364 | D15: =IF(ABS(B15-B12)<0.000001*MAX(1,ABS(B12)),"✓ same","✗") -> ✓ same
A16: Flows after T are still included: (1+R)^(T−t) with t > T just discounts them back to date T, so FV = PV × (1+R)^T always holds.
A18: CASH FLOW TABLE (one row per period)
A19: t | B19: Cash flow CFₜ | C19: Discount factor 1/(1+R)^t | D19: PV of CFₜ | E19: FV factor (1+R)^(T−t) | F19: Value at T of CFₜ
A20: 1 | B20: 40 | C20: =1/(1+$B$5)^A20 -> 0.94339623 | D20: =B20*C20 -> 37.735849 | E20: =(1+$B$5)^($B$6-A20) -> 1.262477 | F20: =B20*E20 -> 50.499078
A21: 2 | B21: 40 | C21: =1/(1+$B$5)^A21 -> 0.88999644 | D21: =B21*C21 -> 35.599858 | E21: =(1+$B$5)^($B$6-A21) -> 1.191016 | F21: =B21*E21 -> 47.64064
A22: 3 | B22: 40 | C22: =1/(1+$B$5)^A22 -> 0.83961928 | D22: =B22*C22 -> 33.584771 | E22: =(1+$B$5)^($B$6-A22) -> 1.1236 | F22: =B22*E22 -> 44.944
A23: 4 | B23: 40 | C23: =1/(1+$B$5)^A23 -> 0.79209366 | D23: =B23*C23 -> 31.683747 | E23: =(1+$B$5)^($B$6-A23) -> 1.06 | F23: =B23*E23 -> 42.4
A24: 5 | B24: 540 | C24: =1/(1+$B$5)^A24 -> 0.74725817 | D24: =B24*C24 -> 403.51941 | E24: =(1+$B$5)^($B$6-A24) -> 1 | F24: =B24*E24 -> 540
A25: 6 | C25: =1/(1+$B$5)^A25 -> 0.70496054 | D25: =B25*C25 -> 0 | E25: =(1+$B$5)^($B$6-A25) -> 0.94339623 | F25: =B25*E25 -> 0
A26: 7 | C26: =1/(1+$B$5)^A26 -> 0.66505711 | D26: =B26*C26 -> 0 | E26: =(1+$B$5)^($B$6-A26) -> 0.88999644 | F26: =B26*E26 -> 0
A27: 8 | C27: =1/(1+$B$5)^A27 -> 0.62741237 | D27: =B27*C27 -> 0 | E27: =(1+$B$5)^($B$6-A27) -> 0.83961928 | F27: =B27*E27 -> 0
A28: 9 | C28: =1/(1+$B$5)^A28 -> 0.59189846 | D28: =B28*C28 -> 0 | E28: =(1+$B$5)^($B$6-A28) -> 0.79209366 | F28: =B28*E28 -> 0
A29: 10 | C29: =1/(1+$B$5)^A29 -> 0.55839478 | D29: =B29*C29 -> 0 | E29: =(1+$B$5)^($B$6-A29) -> 0.74725817 | F29: =B29*E29 -> 0
A30: 11 | C30: =1/(1+$B$5)^A30 -> 0.52678753 | D30: =B30*C30 -> 0 | E30: =(1+$B$5)^($B$6-A30) -> 0.70496054 | F30: =B30*E30 -> 0
A31: 12 | C31: =1/(1+$B$5)^A31 -> 0.49696936 | D31: =B31*C31 -> 0 | E31: =(1+$B$5)^($B$6-A31) -> 0.66505711 | F31: =B31*E31 -> 0
A32: 13 | C32: =1/(1+$B$5)^A32 -> 0.46883902 | D32: =B32*C32 -> 0 | E32: =(1+$B$5)^($B$6-A32) -> 0.62741237 | F32: =B32*E32 -> 0
A33: 14 | C33: =1/(1+$B$5)^A33 -> 0.44230096 | D33: =B33*C33 -> 0 | E33: =(1+$B$5)^($B$6-A33) -> 0.59189846 | F33: =B33*E33 -> 0
A34: 15 | C34: =1/(1+$B$5)^A34 -> 0.41726506 | D34: =B34*C34 -> 0 | E34: =(1+$B$5)^($B$6-A34) -> 0.55839478 | F34: =B34*E34 -> 0
A35: 16 | C35: =1/(1+$B$5)^A35 -> 0.39364628 | D35: =B35*C35 -> 0 | E35: =(1+$B$5)^($B$6-A35) -> 0.52678753 | F35: =B35*E35 -> 0
A36: 17 | C36: =1/(1+$B$5)^A36 -> 0.37136442 | D36: =B36*C36 -> 0 | E36: =(1+$B$5)^($B$6-A36) -> 0.49696936 | F36: =B36*E36 -> 0
... A49: 30 | C49: =1/(1+$B$5)^A49 -> 0.17411013 | D49: =B49*C49 -> 0 | E49: =(1+$B$5)^($B$6-A49) -> 0.23299863 | F49: =B49*E49 -> 0
A50: Totals | B50: =SUM(B20:B49) -> 700 | D50: =SUM(D20:D49) -> 542.12364 | F50: =SUM(F20:F49) -> 725.48372
A51: Undiscounted total (B50) ≠ PV (D50): money later is worth less today. FV (F50) > total: earlier flows earn interest until T.

Sheet 3 Perpetuities
A1: Perpetuities: PV = CF / R Constant-growth: PV = CF / (R − g) (slides 22–25)
A2: A perpetuity pays CF every period forever, starting one period from now (t = 1). Its price is the amount whose interest exactly funds the payments.
A4: A. LEVEL PERPETUITY PV = CF / R
A5: Variable | B5: Your input | C5: Value used / solved | D5: Formula (algebra)
A6: Solve for | B6: PV
A7: Present value PV (price of the perpetuity today) | C7: =IF($B$6="PV",B8/B9,B7) -> 125 | D7: PV = CF / R
A8: Cash flow per period CF (first payment at t = 1) | B8: 10 | C8: =IF($B$6="CF",B7*B9,B8) -> 10 | D8: CF = PV × R (the interest the price earns each period)
A9: Discount rate per period R | B9: 0.08 | C9: =IF($B$6="R",B8/B7,B9) -> 0.08 | D9: R = CF / PV (the yield the perpetuity offers at price PV)
A10: Answer | B10: =IF($B$6="R",TEXT(C9,"0.00%"),IF($B$6="PV",TEXT(C7,"#,##0.00"),TEXT(C8,"#,##0.00"))) -> 125.00 | D10: ="Solved for "&$B$6 -> Solved for PV
A11: Intuition (slide 22): R × PV = CF. Invest $125 at 8% → $10 of interest a year, forever, without touching the $125. So a $10-forever stream is worth $125.
A13: B. CONSTANT-GROWTH PERPETUITY PV = CF / (R − g) (needs g < R)
A14: Variable | B14: Your input | C14: Value used / solved | D14: Formula (algebra)
A15: Solve for | B15: PV
A16: Present value PV | C16: =IF($B$15="PV",IF(B19>=B18,"g must be < R",B17/(B18-B19)),B16) -> 250 | D16: PV = CF / (R − g)
A17: First cash flow CF (at t = 1; then grows at g each period) | B17: 10 | C17: =IF($B$15="CF",B16*(B18-B19),B17) -> 10 | D17: CF = PV × (R − g)
A18: Discount rate per period R | B18: 0.08 | C18: =IF($B$15="R",B17/B16+B19,B18) -> 0.08 | D18: R = CF / PV + g (dividend yield + growth)
A19: Growth rate of the cash flow g | B19: 0.04 | C19: =IF($B$15="g",B18-B17/B16,B19) -> 0.04 | D19: g = R − CF / PV
A20: Answer | B20: =IF(OR($B$15="R",$B$15="g"),TEXT(IF($B$15="R",C18,C19),"0.00%"),IF($B$15="PV",TEXT(C16,"#,##0.00"),TEXT(C17,"#,##0.00"))) -> 250.00 | D20: ="Solved for "&$B$15 -> Solved for PV
A21: Intuition (slide 24): R × PV = CF + g × PV. $250 at 8% earns $20: $10 pays the dividend, the other $10 stays invested so the principal (and next year's dividend) grows 4%. If g ≥ R the sum never converges — PV would be infinite.
A23: C. EXAMPLES FROM THE SLIDES
A24: Example | B24: Solve for | C24: Slide | D24: Formula used | E24: CF | F24: R | G24: g | H24: Model result | I24: Slide answer | J24: Match?
A25: Preferred stock: $10 dividend forever, discount rate 8% | B25: PV | C25: 22–23 | D25: PV = CF / R | E25: 10 | F25: 0.08 | G25: — | H25: =E25/F25 -> 125 | I25: 125 | J25: =IF(ABS(H25-I25)/ABS(I25)<0.005,"✓","✗") -> ✓
A26: Common stock: $10 dividend growing 4% a year, discount rate 8% | B26: PV | C26: 24–25 | D26: PV = CF / (R − g) | E26: 10 | F26: 0.08 | G26: 0.04 | H26: =E26/(F26-G26) -> 250 | I26: 250 | J26: =IF(ABS(H26-I26)/ABS(I26)<0.005,"✓","✗") -> ✓
A27: Growth doubles the price here: the gap (R − g) is what the price is really divided by, so small changes in g move PV a lot.
A29: D. WHY THE FORMULA WORKS — discount each cash flow, add them up, watch the running total converge (uses the solver values above)
A30: Closed-form targets: level CF/R → | B30: =C8/C9 -> 125 | C30: growing CF/(R−g) → | D30: =IF(C19>=C18,"g must be < R",C17/(C18-C19)) -> 250
A31: t | B31: Level CF | C31: PV of level CF CF/(1+R)^t | D31: Running total (level) | E31: Growing CF CF(1+g)^(t−1) | F31: PV of growing CF | G31: Running total (growing) | H31: Target CF/R | I31: Target CF/(R−g)
A32: 1 | B32: =$C$8 -> 10 | C32: =B32/(1+$C$9)^A32 -> 9.2592593 | D32: =SUM($C$32:C32) -> 9.2592593 | E32: =$C$17*(1+$C$19)^(A32-1) -> 10 | F32: =E32/(1+$C$18)^A32 -> 9.2592593 | G32: =SUM($F$32:F32) -> 9.2592593 | H32: =$B$30 -> 125 | I32: =$D$30 -> 250
A33: 2 | B33: =$C$8 -> 10 | C33: =B33/(1+$C$9)^A33 -> 8.5733882 | D33: =SUM($C$32:C33) -> 17.832647 | E33: =$C$17*(1+$C$19)^(A33-1) -> 10.4 | F33: =E33/(1+$C$18)^A33 -> 8.9163237 | G33: =SUM($F$32:F33) -> 18.175583 | H33: =$B$30 -> 125 | I33: =$D$30 -> 250
A34: 3 | B34: =$C$8 -> 10 | C34: =B34/(1+$C$9)^A34 -> 7.9383224 | D34: =SUM($C$32:C34) -> 25.77097 | E34: =$C$17*(1+$C$19)^(A34-1) -> 10.816 | F34: =E34/(1+$C$18)^A34 -> 8.5860895 | G34: =SUM($F$32:F34) -> 26.761673 | H34: =$B$30 -> 125 | I34: =$D$30 -> 250
A35: 4 | B35: =$C$8 -> 10 | C35: =B35/(1+$C$9)^A35 -> 7.3502985 | D35: =SUM($C$32:C35) -> 33.121268 | E35: =$C$17*(1+$C$19)^(A35-1) -> 11.24864 | F35: =E35/(1+$C$18)^A35 -> 8.2680862 | G35: =SUM($F$32:F35) -> 35.029759 | H35: =$B$30 -> 125 | I35: =$D$30 -> 250
A36: 5 | B36: =$C$8 -> 10 | C36: =B36/(1+$C$9)^A36 -> 6.805832 | D36: =SUM($C$32:C36) -> 39.9271 | E36: =$C$17*(1+$C$19)^(A36-1) -> 11.698586 | F36: =E36/(1+$C$18)^A36 -> 7.9618608 | G36: =SUM($F$32:F36) -> 42.99162 | H36: =$B$30 -> 125 | I36: =$D$30 -> 250
A37: 6 | B37: =$C$8 -> 10 | C37: =B37/(1+$C$9)^A37 -> 6.3016963 | D37: =SUM($C$32:C37) -> 46.228797 | E37: =$C$17*(1+$C$19)^(A37-1) -> 12.166529 | F37: =E37/(1+$C$18)^A37 -> 7.6669771 | G37: =SUM($F$32:F37) -> 50.658597 | H37: =$B$30 -> 125 | I37: =$D$30 -> 250
A38: 7 | B38: =$C$8 -> 10 | C38: =B38/(1+$C$9)^A38 -> 5.834904 | D38: =SUM($C$32:C38) -> 52.063701 | E38: =$C$17*(1+$C$19)^(A38-1) -> 12.65319 | F38: =E38/(1+$C$18)^A38 -> 7.3830149 | G38: =SUM($F$32:F38) -> 58.041611 | H38: =$B$30 -> 125 | I38: =$D$30 -> 250
A39: 8 | B39: =$C$8 -> 10 | C39: =B39/(1+$C$9)^A39 -> 5.4026888 | D39: =SUM($C$32:C39) -> 57.466389 | E39: =$C$17*(1+$C$19)^(A39-1) -> 13.159318 | F39: =E39/(1+$C$18)^A39 -> 7.1095699 | G39: =SUM($F$32:F39) -> 65.151181 | H39: =$B$30 -> 125 | I39: =$D$30 -> 250
A40: 9 | B40: =$C$8 -> 10 | C40: =B40/(1+$C$9)^A40 -> 5.0024897 | D40: =SUM($C$32:C40) -> 62.468879 | E40: =$C$17*(1+$C$19)^(A40-1) -> 13.685691 | F40: =E40/(1+$C$18)^A40 -> 6.8462525 | G40: =SUM($F$32:F40) -> 71.997434 | H40: =$B$30 -> 125 | I40: =$D$30 -> 250
A41: 10 | B41: =$C$8 -> 10 | C41: =B41/(1+$C$9)^A41 -> 4.6319349 | D41: =SUM($C$32:C41) -> 67.100814 | E41: =$C$17*(1+$C$19)^(A41-1) -> 14.233118 | F41: =E41/(1+$C$18)^A41 -> 6.5926876 | G41: =SUM($F$32:F41) -> 78.590122 | H41: =$B$30 -> 125 | I41: =$D$30 -> 250
A42: 11 | B42: =$C$8 -> 10 | C42: =B42/(1+$C$9)^A42 -> 4.2888286 | D42: =SUM($C$32:C42) -> 71.389643 | E42: =$C$17*(1+$C$19)^(A42-1) -> 14.802443 | F42: =E42/(1+$C$18)^A42 -> 6.348514 | G42: =SUM($F$32:F42) -> 84.938636 | H42: =$B$30 -> 125 | I42: =$D$30 -> 250
A43: 12 | B43: =$C$8 -> 10 | C43: =B43/(1+$C$9)^A43 -> 3.9711376 | D43: =SUM($C$32:C43) -> 75.36078 | E43: =$C$17*(1+$C$19)^(A43-1) -> 15.394541 | F43: =E43/(1+$C$18)^A43 -> 6.1133839 | G43: =SUM($F$32:F43) -> 91.052019 | H43: =$B$30 -> 125 | I43: =$D$30 -> 250
... A131: 100 | B131: =$C$8 -> 10 | C131: =B131/(1+$C$9)^A131 -> 0.0045459479 | D131: =SUM($C$32:C131) -> 124.94318 | E131: =$C$17*(1+$C$19)^(A131-1) -> 485.6245 | F131: =E131/(1+$C$18)^A131 -> 0.22076237 | G131: =SUM($F$32:F131) -> 244.26018 | H131: =$B$30 -> 125 | I131: =$D$30 -> 250
...

Sheet 4 Annuities
A1: Annuities: PV = CF/R × [1 − 1/(1+R)^T] Growing: PV = CF/(R−g) × [1 − (1+g)^T/(1+R)^T] (slide 26)
A2: An annuity is a perpetuity that stops after T payments = perpetuity from t=1 minus a perpetuity from t=T+1. Default = credit-card example (slides 27–28).
A4: A. LEVEL ANNUITY PV = CF/R × [1 − 1/(1+R)^T]
A5: Variable | B5: Your input | C5: Value used / solved | D5: Formula (algebra)
A6: Solve for | B6: CF
A7: Present value PV (loan balance today / price of the annuity) | B7: 16000 | C7: =IF($B$6="PV",B8/B9*(1-1/(1+B9)^B10),B7) -> 16000 | D7: PV = CF/R × [1 − 1/(1+R)^T]
A8: Cash flow per period CF (level payment, first one at t = 1) | C8: =IF($B$6="CF",B7*B9/(1-1/(1+B9)^B10),B8) -> 469.99999 | D8: CF = PV × R / [1 − 1/(1+R)^T] (divide PV by the annuity factor)
A9: Rate per period R (monthly rate with monthly payments!) | B9: 0.015 | C9: =IF($B$6="R",RATE(B10,-B8,B7),B9) -> 0.015 | D9: No closed form for R → Excel iterates: =RATE(T, −CF, PV)
A10: Number of periods T (months here) | B10: 48 | C10: =IF($B$6="T",-LN(1-B7*B9/B8)/LN(1+B9),B10) -> 48 | D10: T = −ln(1 − PV×R/CF) / ln(1+R) (needs CF > PV×R, or the debt never shrinks)
A11: Answer | B11: =IF($B$6="R",TEXT(C9,"0.00%"),IF($B$6="T",TEXT(C10,"0.00")&" periods",IF($B$6="PV",TEXT(C7,"#,##0.00"),TEXT(C8,"#,##0.00")))) -> 470.00 | D11: ="Solved for "&$B$6 -> Solved for CF
A12: Excel built-in function (cross-check) | B12: =IF($B$6="PV",PV(B9,B10,-B8),IF($B$6="CF",PMT(B9,B10,-B7),IF($B$6="R",RATE(B10,-B8,B7),NPER(B9,-B8,B7)))) -> 469.99999 | D12: =PV(R,T,−CF) · =PMT(R,T,−PV) · =RATE(T,−CF,PV) · =NPER(R,−CF,PV)
A14: Where the formula comes from (slide 26) and the FV of the same payments
A15: Perpetuity starting at t = 1: CF / R | B15: =C8/C9 -> 31333.333
A16: Less: perpetuity starting at t = T+1, discounted to today: CF/R × 1/(1+R)^T | B16: =C8/C9/(1+C9)^C10 -> 15333.333
A17: = Annuity PV | B17: =B15-B16 -> 16000 | D17: =IF(ABS(B17-C7)<0.000001*MAX(1,ABS(C7)),"✓ equals the PV in the solver","✗") -> ✓ equals the PV in the solver
A18: Annuity factor [1 − 1/(1+R)^T] / R (PV of $1 per period) | B18: =(1-1/(1+C9)^C10)/C9 -> 34.042554 | D18: PV = CF × annuity factor, so CF = PV / annuity factor
A19: Future value at T of the payments: FV = CF × [(1+R)^T − 1] / R | B19: =C8*((1+C9)^C10-1)/C9 -> 32695.653 | D19: Multiply the PV formula by (1+R)^T — used in slide 28's savings question
A20: Same thing via PV × (1+R)^T | B20: =C7*(1+C9)^C10 -> 32695.653 | D20: =IF(ABS(B20-B19)<0.000001*MAX(1,ABS(B19)),"✓ same","✗") -> ✓ same
A22: B. GROWING ANNUITY PV = CF/(R−g) × [1 − ((1+g)/(1+R))^T]
A23: Variable | B23: Your input | C23: Value used / solved | D23: Formula (algebra)
A24: Solve for | B24: CF
A25: Present value PV | B25: 16000 | C25: =IF($B$24="PV",IF(B27=B28,B26*B29/(1+B27),B26/(B27-B28)*(1-((1+B28)/(1+B27))^B29)),B25) -> 16000 | D25: PV = CF/(R−g) × [1 − ((1+g)/(1+R))^T] (if g = R exactly: PV = CF × T/(1+R))
A26: First cash flow CF (at t = 1; grows at g each period after) | C26: =IF($B$24="CF",B25*(B27-B28)/(1-((1+B28)/(1+B27))^B29),B26) -> 422.97688 | D26: CF = PV × (R−g) / [1 − ((1+g)/(1+R))^T]
A27: Rate per period R | B27: 0.015 | C27: =B27 -> 0.015 | D27: No closed form for R → enter it (or Data ▸ What-If ▸ Goal Seek on the PV cell)
A28: Growth rate of the cash flow g | B28: 0.005 | C28: =B28 -> 0.005 | D28: No closed form for g → enter it (or Goal Seek)
A29: Number of periods T | B29: 48 | C29: =IF($B$24="T",LN(1-B25*(B27-B28)/B26)/LN((1+B28)/(1+B27)),B29) -> 48 | D29: T = ln(1 − PV(R−g)/CF) / ln((1+g)/(1+R))
A30: Answer | B30: =IF($B$24="T",TEXT(C29,"0.00")&" periods",IF($B$24="PV",TEXT(C25,"#,##0.00"),TEXT(C26,"#,##0.00"))) -> 422.98 | D30: ="Solved for "&$B$24 -> Solved for CF
A31: Growing perpetuity starting at t = 1: CF / (R − g) | B31: =C26/(C27-C28) -> 42297.688
A32: Less: growing perpetuity from t = T+1 (first flow CF(1+g)^T), discounted: CF(1+g)^T/(R−g) × 1/(1+R)^T | B32: =C26*(1+C28)^C29/(C27-C28)/(1+C27)^C29 -> 26297.688
A33: = Growing annuity PV | B33: =B31-B32 -> 16000 | D33: =IF(ABS(B33-C25)<0.000001*MAX(1,ABS(C25)),"✓ equals the PV in the solver","✗") -> ✓ equals the PV in the solver
A34: Future value at T: FV = CF/(R−g) × [(1+R)^T − (1+g)^T] = PV × (1+R)^T | B34: =C26/(C27-C28)*((1+C27)^C29-(1+C28)^C29) -> 32695.653 | D34: =IF(ABS(B34-C25*(1+C27)^C29)<0.000001*MAX(1,ABS(B34)),"✓ equals PV × (1+R)^T","✗") -> ✓ equals PV × (1+R)^T
A36: C. CREDIT-CARD EXAMPLE (slides 27–28) — which formula, and why
A37: Debt today PV | B37: 16000
A38: Interest rate per month R | B38: 0.015
A39: Months to pay off T | B39: 48
A40: Growth of payments g (from income growth) | B40: 0.005
A41: Question | B41: Model result | C41: Slide answer | D41: Which formula and why | E41: Match?
A42: Q1. Minimum level monthly payment to be debt-free in 48 months | B42: =B37*B38/(1-1/(1+B38)^B39) -> 469.99999 | C42: 470 | D42: Level annuity, solve for CF: equal payments for a finite T whose PV must equal today's debt. 16 = CF × [1 − 1/1.015^48]/0.015 | E42: =IF(ABS(B42-C42)/ABS(C42)<0.005,"✓","✗") -> ✓
A43: Q2. First payment if payments grow 0.5% a month | B43: =B37*(B38-B40)/(1-((1+B40)/(1+B38))^B39) -> 422.97688 | C43: 423 | D43: Growing annuity, solve for CF: same PV, but the payment stream grows at g, so the first payment can be lower. | E43: =IF(ABS(B43-C43)/ABS(C43)<0.005,"✓","✗") -> ✓
A44: Q3. If there were no debt and the Q1 payment were saved at 1.5%/month, savings after 4 years | B44: =B42*((1+B38)^B39-1)/B38 -> 32695.653 | C44: 32696 | D44: FV of an annuity: CF × [(1+R)^T − 1]/R. Each deposit compounds until month 48. | E44: =IF(ABS(B44-C44)/ABS(C44)<0.005,"✓","✗") -> ✓
...

Sheet 5 Credit Card Schedule
A1: Month by month: why the annuity formula works (credit-card example, slides 27–28)
A2: Inputs link to sheet '4 Annuities' (green). Balance grows by interest, shrinks by the payment, and lands on zero exactly at month T.
A4: LINKED INPUTS | D4: WHAT THE SCHEDULE SHOWS
A5: Debt today PV | B5: ='4 Annuities'!C7 -> 16000 | D5: Balance after the last level payment (should be 0) | G5: =ROUND(INDEX(E17:E136,B7),2) -> 0
A6: Monthly rate R | B6: ='4 Annuities'!C9 -> 0.015 | D6: Balance after the last growing payment (should be 0) | G6: =ROUND(INDEX(H17:H136,B12),2) -> 0
A7: Months T | B7: ='4 Annuities'!C10 -> 48 | D7: Savings after T months of depositing the level payment | G7: =INDEX(I17:I136,B7) -> 32695.653
A8: Level payment CF | B8: ='4 Annuities'!C8 -> 469.99999 | D8: FV of the debt PV × (1+R)^T | G8: =B5*(1+B6)^B7 -> 32695.653
A9: Growing plan: debt PV | B9: ='4 Annuities'!C25 -> 16000 | D9: =IF(ABS(G7-G8)<0.01,"✓ savings = FV of the debt (slide 28)","✗") -> ✓ savings = FV of the debt (slide 28)
A10: Growing plan: monthly rate R | B10: ='4 Annuities'!C27 -> 0.015 | D10: Total interest paid, level plan | G10: =SUM(C17:C136) -> 6559.9997
A11: Growing plan: growth g | B11: ='4 Annuities'!C28 -> 0.005 | D11: Total paid, level plan (= T × CF) | G11: =SUM(D17:D136) -> 22560
A12: Growing plan: months T | B12: ='4 Annuities'!C29 -> 48 | D12: Total paid, growing plan | G12: =SUM(G17:G136) -> 22882.132
A13: Growing plan: first payment CF₁ | B13: ='4 Annuities'!C26 -> 422.97688 | D13: Growing payments start lower but end higher, so the total paid is larger (the debt is outstanding longer).
A15: SCHEDULE (rows beyond T stay blank; the closing balances show 0 once the debt is repaid)
A16: Month t | B16: Opening balance | C16: Interest R × opening | D16: Level payment | E16: Closing balance (level) | F16: Opening balance (growing) | G16: Growing payment CF₁(1+g)^(t−1) | H16: Closing balance (growing) | I16: Savings if the level payment were saved at R
A17: 1 | B17: =IF(A17>$B$7,"",IF(A17=1,$B$5,E16)) -> 16000 | C17: =IF(A17>$B$7,"",B17*$B$6) -> 240 | D17: =IF(A17>$B$7,"",$B$8) -> 469.99999 | E17: =IF(A17>$B$7,0,IF(ABS(B17+C17-D17)<0.005,0,B17+C17-D17)) -> 15770 | F17: =IF(A17>$B$12,"",IF(A17=1,$B$9,H16)) -> 16000 | G17: =IF(A17>$B$12,"",$B$13*(1+$B$11)^(A17-1)) -> 422.97688 | H17: =IF(A17>$B$12,0,IF(ABS(F17*(1+$B$10)-G17)<0.005,0,F17*(1+$B$10)-G17)) -> 15817.023 | I17: =IF(A17>$B$7,0,$B$8) -> 469.99999
A18: 2 | B18: =IF(A18>$B$7,"",IF(A18=1,$B$5,E17)) -> 15770 | C18: =IF(A18>$B$7,"",B18*$B$6) -> 236.55 | D18: =IF(A18>$B$7,"",$B$8) -> 469.99999 | E18: =IF(A18>$B$7,0,IF(ABS(B18+C18-D18)<0.005,0,B18+C18-D18)) -> 15536.55 | F18: =IF(A18>$B$12,"",IF(A18=1,$B$9,H17)) -> 15817.023 | G18: =IF(A18>$B$12,"",$B$13*(1+$B$11)^(A18-1)) -> 425.09176 | H18: =IF(A18>$B$12,0,IF(ABS(F18*(1+$B$10)-G18)<0.005,0,F18*(1+$B$10)-G18)) -> 15629.187 | I18: =IF(A18>$B$7,I17,I17*(1+$B$6)+$B$8) -> 947.04999
A19: 3 | B19: =IF(A19>$B$7,"",IF(A19=1,$B$5,E18)) -> 15536.55 | C19: =IF(A19>$B$7,"",B19*$B$6) -> 233.04825 | D19: =IF(A19>$B$7,"",$B$8) -> 469.99999 | E19: =IF(A19>$B$7,0,IF(ABS(B19+C19-D19)<0.005,0,B19+C19-D19)) -> 15299.598 | F19: =IF(A19>$B$12,"",IF(A19=1,$B$9,H18)) -> 15629.187 | G19: =IF(A19>$B$12,"",$B$13*(1+$B$11)^(A19-1)) -> 427.21722 | H19: =IF(A19>$B$12,0,IF(ABS(F19*(1+$B$10)-G19)<0.005,0,F19*(1+$B$10)-G19)) -> 15436.407 | I19: =IF(A19>$B$7,I18,I18*(1+$B$6)+$B$8) -> 1431.2557
A20: 4 | B20: =IF(A20>$B$7,"",IF(A20=1,$B$5,E19)) -> 15299.598 | C20: =IF(A20>$B$7,"",B20*$B$6) -> 229.49397 | D20: =IF(A20>$B$7,"",$B$8) -> 469.99999 | E20: =IF(A20>$B$7,0,IF(ABS(B20+C20-D20)<0.005,0,B20+C20-D20)) -> 15059.092 | F20: =IF(A20>$B$12,"",IF(A20=1,$B$9,H19)) -> 15436.407 | G20: =IF(A20>$B$12,"",$B$13*(1+$B$11)^(A20-1)) -> 429.3533 | H20: =IF(A20>$B$12,0,IF(ABS(F20*(1+$B$10)-G20)<0.005,0,F20*(1+$B$10)-G20)) -> 15238.6 | I20: =IF(A20>$B$7,I19,I19*(1+$B$6)+$B$8) -> 1922.7246
A21: 5 | B21: =IF(A21>$B$7,"",IF(A21=1,$B$5,E20)) -> 15059.092 | C21: =IF(A21>$B$7,"",B21*$B$6) -> 225.88638 | D21: =IF(A21>$B$7,"",$B$8) -> 469.99999 | E21: =IF(A21>$B$7,0,IF(ABS(B21+C21-D21)<0.005,0,B21+C21-D21)) -> 14814.979 | F21: =IF(A21>$B$12,"",IF(A21=1,$B$9,H20)) -> 15238.6 | G21: =IF(A21>$B$12,"",$B$13*(1+$B$11)^(A21-1)) -> 431.50007 | H21: =IF(A21>$B$12,0,IF(ABS(F21*(1+$B$10)-G21)<0.005,0,F21*(1+$B$10)-G21)) -> 15035.679 | I21: =IF(A21>$B$7,I20,I20*(1+$B$6)+$B$8) -> 2421.5654
A22: 6 | B22: =IF(A22>$B$7,"",IF(A22=1,$B$5,E21)) -> 14814.979 | C22: =IF(A22>$B$7,"",B22*$B$6) -> 222.22468 | D22: =IF(A22>$B$7,"",$B$8) -> 469.99999 | E22: =IF(A22>$B$7,0,IF(ABS(B22+C22-D22)<0.005,0,B22+C22-D22)) -> 14567.203 | F22: =IF(A22>$B$12,"",IF(A22=1,$B$9,H21)) -> 15035.679 | G22: =IF(A22>$B$12,"",$B$13*(1+$B$11)^(A22-1)) -> 433.65757 | H22: =IF(A22>$B$12,0,IF(ABS(F22*(1+$B$10)-G22)<0.005,0,F22*(1+$B$10)-G22)) -> 14827.557 | I22: =IF(A22>$B$7,I21,I21*(1+$B$6)+$B$8) -> 2927.8889
A23: 7 | B23: =IF(A23>$B$7,"",IF(A23=1,$B$5,E22)) -> 14567.203 | C23: =IF(A23>$B$7,"",B23*$B$6) -> 218.50805 | D23: =IF(A23>$B$7,"",$B$8) -> 469.99999 | E23: =IF(A23>$B$7,0,IF(ABS(B23+C23-D23)<0.005,0,B23+C23-D23)) -> 14315.711 | F23: =IF(A23>$B$12,"",IF(A23=1,$B$9,H22)) -> 14827.557 | G23: =IF(A23>$B$12,"",$B$13*(1+$B$11)^(A23-1)) -> 435.82586 | H23: =IF(A23>$B$12,0,IF(ABS(F23*(1+$B$10)-G23)<0.005,0,F23*(1+$B$10)-G23)) -> 14614.144 | I23: =IF(A23>$B$7,I22,I22*(1+$B$6)+$B$8) -> 3441.8072
A24: 8 | B24: =IF(A24>$B$7,"",IF(A24=1,$B$5,E23)) -> 14315.711 | C24: =IF(A24>$B$7,"",B24*$B$6) -> 214.73567 | D24: =IF(A24>$B$7,"",$B$8) -> 469.99999 | E24: =IF(A24>$B$7,0,IF(ABS(B24+C24-D24)<0.005,0,B24+C24-D24)) -> 14060.447 | F24: =IF(A24>$B$12,"",IF(A24=1,$B$9,H23)) -> 14614.144 | G24: =IF(A24>$B$12,"",$B$13*(1+$B$11)^(A24-1)) -> 438.00499 | H24: =IF(A24>$B$12,0,IF(ABS(F24*(1+$B$10)-G24)<0.005,0,F24*(1+$B$10)-G24)) -> 14395.351 | I24: =IF(A24>$B$7,I23,I23*(1+$B$6)+$B$8) -> 3963.4343
A25: 9 | B25: =IF(A25>$B$7,"",IF(A25=1,$B$5,E24)) -> 14060.447 | C25: =IF(A25>$B$7,"",B25*$B$6) -> 210.90671 | D25: =IF(A25>$B$7,"",$B$8) -> 469.99999 | E25: =IF(A25>$B$7,0,IF(ABS(B25+C25-D25)<0.005,0,B25+C25-D25)) -> 13801.354 | F25: =IF(A25>$B$12,"",IF(A25=1,$B$9,H24)) -> 14395.351 | G25: =IF(A25>$B$12,"",$B$13*(1+$B$11)^(A25-1)) -> 440.19501 | H25: =IF(A25>$B$12,0,IF(ABS(F25*(1+$B$10)-G25)<0.005,0,F25*(1+$B$10)-G25)) -> 14171.087 | I25: =IF(A25>$B$7,I24,I24*(1+$B$6)+$B$8) -> 4492.8858
A26: 10 | B26: =IF(A26>$B$7,"",IF(A26=1,$B$5,E25)) -> 13801.354 | C26: =IF(A26>$B$7,"",B26*$B$6) -> 207.02031 | D26: =IF(A26>$B$7,"",$B$8) -> 469.99999 | E26: =IF(A26>$B$7,0,IF(ABS(B26+C26-D26)<0.005,0,B26+C26-D26)) -> 13538.374 | F26: =IF(A26>$B$12,"",IF(A26=1,$B$9,H25)) -> 14171.087 | G26: =IF(A26>$B$12,"",$B$13*(1+$B$11)^(A26-1)) -> 442.39599 | H26: =IF(A26>$B$12,0,IF(ABS(F26*(1+$B$10)-G26)<0.005,0,F26*(1+$B$10)-G26)) -> 13941.257 | I26: =IF(A26>$B$7,I25,I25*(1+$B$6)+$B$8) -> 5030.2791
A27: 11 | B27: =IF(A27>$B$7,"",IF(A27=1,$B$5,E26)) -> 13538.374 | C27: =IF(A27>$B$7,"",B27*$B$6) -> 203.07561 | D27: =IF(A27>$B$7,"",$B$8) -> 469.99999 | E27: =IF(A27>$B$7,0,IF(ABS(B27+C27-D27)<0.005,0,B27+C27-D27)) -> 13271.45 | F27: =IF(A27>$B$12,"",IF(A27=1,$B$9,H26)) -> 13941.257 | G27: =IF(A27>$B$12,"",$B$13*(1+$B$11)^(A27-1)) -> 444.60797 | H27: =IF(A27>$B$12,0,IF(ABS(F27*(1+$B$10)-G27)<0.005,0,F27*(1+$B$10)-G27)) -> 13705.768 | I27: =IF(A27>$B$7,I26,I26*(1+$B$6)+$B$8) -> 5575.7333
A28: 12 | B28: =IF(A28>$B$7,"",IF(A28=1,$B$5,E27)) -> 13271.45 | C28: =IF(A28>$B$7,"",B28*$B$6) -> 199.07175 | D28: =IF(A28>$B$7,"",$B$8) -> 469.99999 | E28: =IF(A28>$B$7,0,IF(ABS(B28+C28-D28)<0.005,0,B28+C28-D28)) -> 13000.521 | F28: =IF(A28>$B$12,"",IF(A28=1,$B$9,H27)) -> 13705.768 | G28: =IF(A28>$B$12,"",$B$13*(1+$B$11)^(A28-1)) -> 446.83101 | H28: =IF(A28>$B$12,0,IF(ABS(F28*(1+$B$10)-G28)<0.005,0,F28*(1+$B$10)-G28)) -> 13464.523 | I28: =IF(A28>$B$7,I27,I27*(1+$B$6)+$B$8) -> 6129.3693
A29: 13 | B29: =IF(A29>$B$7,"",IF(A29=1,$B$5,E28)) -> 13000.521 | C29: =IF(A29>$B$7,"",B29*$B$6) -> 195.00782 | D29: =IF(A29>$B$7,"",$B$8) -> 469.99999 | E29: =IF(A29>$B$7,0,IF(ABS(B29+C29-D29)<0.005,0,B29+C29-D29)) -> 12725.529 | F29: =IF(A29>$B$12,"",IF(A29=1,$B$9,H28)) -> 13464.523 | G29: =IF(A29>$B$12,"",$B$13*(1+$B$11)^(A29-1)) -> 449.06516 | H29: =IF(A29>$B$12,0,IF(ABS(F29*(1+$B$10)-G29)<0.005,0,F29*(1+$B$10)-G29)) -> 13217.426 | I29: =IF(A29>$B$7,I28,I28*(1+$B$6)+$B$8) -> 6691.3098
... A136: 120 | B136: =IF(A136>$B$7,"",IF(A136=1,$B$5,E135)) | C136: =IF(A136>$B$7,"",B136*$B$6) | D136: =IF(A136>$B$7,"",$B$8) | E136: =IF(A136>$B$7,0,IF(ABS(B136+C136-D136)<0.005,0,B136+C136-D136)) -> 0 | F136: =IF(A136>$B$12,"",IF(A136=1,$B$9,H135)) | G136: =IF(A136>$B$12,"",$B$13*(1+$B$11)^(A136-1)) | H136: =IF(A136>$B$12,0,IF(ABS(F136*(1+$B$10)-G136)<0.005,0,F136*(1+$B$10)-G136)) -> 0 | I136: =IF(A136>$B$7,I135,I135*(1+$B$6)+$B$8) -> 32695.653
A137: Closing = opening × (1+R) − payment. The first months are mostly interest; as the balance falls, more of each payment repays principal.

Sheet 6 Compounding & EAR
A1: Frequency of compounding, effective annual rate, continuous compounding (slides 29–34)
A2: APR (quoted rate) is what gets advertised. EAR is what you actually earn or pay in a year once interest compounds m times.
A4: A. QUOTED RATE (APR) ↔ EFFECTIVE ANNUAL RATE (EAR) EAR = (1 + APR/m)^m − 1
A5: Variable | B5: Your input | C5: Value used / solved | D5: Formula (algebra)
A6: Solve for | B6: EAR
A7: Quoted annual rate APR | B7: 0.18 | C7: =IF($B$6="APR",B9*((1+B8)^(1/B9)-1),B7) -> 0.18 | D7: APR = m × [(1 + EAR)^(1/m) − 1]
A8: Effective annual rate EAR | C8: =IF($B$6="EAR",(1+B7/B9)^B9-1,B8) -> 0.19561817 | D8: EAR = (1 + APR/m)^m − 1
A9: Compounding periods per year m | B9: 12 | C9: =B9 -> 12 | D9: 1 annual · 2 semi-annual · 4 quarterly · 12 monthly · 52 weekly · 365 daily
A10: Rate per compounding period = APR / m | B10: =C7/C9 -> 0.015 | D10: The rate actually charged each period (1.5% per month on the slide)
A11: Answer | B11: =IF($B$6="EAR",TEXT(C8,"0.00%"),TEXT(C7,"0.00%")) -> 19.56% | D11: ="Solved for "&$B$6 -> Solved for EAR
A12: Excel built-in function (cross-check) | B12: =IF($B$6="EAR",EFFECT(B7,B9),NOMINAL(B8,B9)) -> 0.19561817 | D12: =EFFECT(APR, m) · =NOMINAL(EAR, m)
A13: Continuous compounding (m → ∞): EAR = e^APR − 1 · APR = ln(1 + EAR) | B13: =IF($B$6="EAR",EXP(B7)-1,LN(1+B8)) -> 0.19721736 | D13: (1 + r/m)^m → e^r as m grows without bound; e = 2.71828… (slide 31)
A14: Slide 29: 18% APR monthly → 19.56% EAR. Quoting the APR makes a loan look cheaper than it is.
A16: B. ONE QUOTED RATE, MANY COMPOUNDING FREQUENCIES (slide 30)
A17: Quoted rate APR | B17: 0.1
A18: Frequency | B18: m | C18: Rate per period APR/m | D18: EAR (1 + APR/m)^m − 1 | E18: Slide answer | F18: Match?
A19: Annual | B19: 1 | C19: =$B$17/B19 -> 0.1 | D19: =(1+C19)^B19-1 -> 0.1 | E19: 0.1 | F19: =IF(ABS(D19-E19)<0.0001,"✓","✗") -> ✓
A20: Semi-annual | B20: 2 | C20: =$B$17/B20 -> 0.05 | D20: =(1+C20)^B20-1 -> 0.1025 | E20: 0.1025 | F20: =IF(ABS(D20-E20)<0.0001,"✓","✗") -> ✓
A21: Quarterly | B21: 4 | C21: =$B$17/B21 -> 0.025 | D21: =(1+C21)^B21-1 -> 0.10381289 | E21: 0.1038 | F21: =IF(ABS(D21-E21)<0.0001,"✓","✗") -> ✓
A22: Monthly | B22: 12 | C22: =$B$17/B22 -> 0.0083333333 | D22: =(1+C22)^B22-1 -> 0.10471307 | E22: 0.1047 | F22: =IF(ABS(D22-E22)<0.0001,"✓","✗") -> ✓
A23: Weekly | B23: 52 | C23: =$B$17/B23 -> 0.0019230769 | D23: =(1+C23)^B23-1 -> 0.10506479 | E23: 0.1051 | F23: =IF(ABS(D23-E23)<0.0001,"✓","✗") -> ✓
A24: Daily | B24: 365 | C24: =$B$17/B24 -> 0.0002739726 | D24: =(1+C24)^B24-1 -> 0.10515578 | E24: 0.10516 | F24: =IF(ABS(D24-E24)<0.0001,"✓","✗") -> ✓
A25: Continuous (m → ∞) | B25: ∞ | C25: → 0 | D25: =EXP($B$17)-1 -> 0.10517092 | E25: 0.10517 | F25: =IF(ABS(D25-E25)<0.0001,"✓","✗") -> ✓
A26: Each step up in frequency adds less and less: the EAR converges to e^APR − 1. Slide answers are rounded to 2–3 decimals.
A28: C. FV AND FREQUENCY OF COMPOUNDING FV = PV × (1 + APR/m)^(T×m) = PV × (1 + EAR)^T (slide 32)
A29: Amount invested today PV | B29: 100 | D29: Two routes, one answer: convert APR to a per-period rate and count T×m periods, or convert APR to an EAR and count T years. With e^(R×T) the number of periods is infinite but the answer is finite.
A30: Quoted rate APR | B30: 0.1
A31: Compounding periods per year m | B31: 2
A32: Years T | B32: 20
A33: EAR = (1 + APR/m)^m − 1 | B33: =(1+B30/B31)^B31-1 -> 0.1025
A34: FV, route 1: PV × (1 + EAR)^T | B34: =B29*(1+B33)^B32 -> 703.99887
A35: FV, route 2: PV × (1 + APR/m)^(T × m) | B35: =B29*(1+B30/B31)^(B32*B31) -> 703.99887 | C35: =IF(ABS(B35-B34)<0.000001*MAX(1,ABS(B34)),"✓ same answer","✗") -> ✓ same answer
A36: FV with continuous compounding: PV × e^(APR × T) | B36: =B29*EXP(B30*B32) -> 738.90561
A37: FV with annual compounding (m = 1): PV × (1 + APR)^T | B37: =B29*(1+B30)^B32 -> 672.74999
A38: Extra from compounding continuously instead of annually | B38: =B36-B37 -> 66.155615
A40: D. CHART DATA — FV of the amount above at the quoted rate above (slide 32)
A41: Year | B41: Annual (m = 1) | C41: Semi-annual (m = 2) | D41: Monthly (m = 12) | E41: Continuous
A42: 0 | B42: =$B$29*(1+$B$30/1)^(A42*1) -> 100 | C42: =$B$29*(1+$B$30/2)^(A42*2) -> 100 | D42: =$B$29*(1+$B$30/12)^(A42*12) -> 100 | E42: =$B$29*EXP($B$30*A42) -> 100
A43: 1 | B43: =$B$29*(1+$B$30/1)^(A43*1) -> 110 | C43: =$B$29*(1+$B$30/2)^(A43*2) -> 110.25 | D43: =$B$29*(1+$B$30/12)^(A43*12) -> 110.47131 | E43: =$B$29*EXP($B$30*A43) -> 110.51709
A44: 2 | B44: =$B$29*(1+$B$30/1)^(A44*1) -> 121 | C44: =$B$29*(1+$B$30/2)^(A44*2) -> 121.55062 | D44: =$B$29*(1+$B$30/12)^(A44*12) -> 122.0391 | E44: =$B$29*EXP($B$30*A44) -> 122.14028
...
